<mujoco model="two_1D_blocks">
    <!-- Use degrees for euler angles, local coordinates for bodies -->
    <compiler angle="degree" coordinate="local"/>

    <!-- Simulation options: turn off gravity so blocks stay in the same z-plane -->
    <option timestep="0.002" iterations="1" gravity="0 0 0"/>

    <!-- Default visual properties for geoms and bodies (optional) -->
    <default>
        <!-- Give a small friction, etc. for collisions -->
        <geom friction="0.7 0.1 0.1" density="1000" margin="0.002" condim="3"/>
    </default>

    <!-- Some simple lighting and texturing -->
    <visual>
        <headlight ambient="0.4 0.4 0.4" diffuse="0.8 0.8 0.8" specular="0.1 0.1 0.1"/>
        <map znear="0.01"/>
        <quality shadowsize="2048"/>
    </visual>

    <asset>
        <!-- A simple skybox gradient background -->
        <texture name="skybox" type="skybox" builtin="gradient"
                 rgb1="0.4 0.6 0.8" rgb2="0 0 0" width="800" height="800"
                 mark="random" markrgb="1 1 1"/>
        <!-- A simple checkered plane texture -->
        <texture name="grid" type="2d" builtin="checker"
                 rgb1="0.1 0.2 0.3"  rgb2="0.2 0.3 0.4"
                 width="300" height="300" mark="edge" markrgb="0.2 0.3 0.4"/>
        <material name="grid" texture="grid" texrepeat="1 1" texuniform="true" reflectance="0.2"/>

        <!-- Materials for the blocks -->
        <material name="block1_mat" rgba="0.8 0.2 0.2 1"/>
        <material name="block2_mat" rgba="0.2 0.2 0.8 1"/>
    </asset>

    <worldbody>
        <!-- A floor plane, just for visual reference. It's at z=0. -->
        <geom name="floor" pos="0 0 0" size="4 4 0.1" type="plane" material="grid"/>

        <!-- Block 1: restricted to slide along x-axis only. -->
        <body name="block1" pos="0 0 0.0">
            <!-- A slide joint along x-axis only -->
            <joint name="slide1" type="slide" axis="1 0 0"/>
            <!-- The box representing the block -->
            <geom name="block1_geom" type="box" size="0.05 0.05 0.05" material="block1_mat"/>
        </body>

        <!-- Block 2: also restricted to slide along x-axis only, starts to the right of Block 1. -->
        <body name="block2" pos="0.5 0 0.0">
            <joint name="slide2" type="slide" axis="1 0 0"/>
            <geom name="block2_geom" type="box" size="0.05 0.05 0.05" material="block2_mat"/>
        </body>
    </worldbody>
</mujoco>