<mujoco model="cart">
    <option timestep="0.001" iterations="1" solver="Newton" integrator="Euler">
        <flag contact="disable"/>
    </option>

    <visual>
        <headlight ambient=".4 .4 .4" diffuse=".8 .8 .8" specular="0.1 0.1 0.1"/>
        <map znear=".01"/>
        <quality shadowsize="2048"/>
    </visual>

    <asset>
        <texture name="skybox" type="skybox" builtin="gradient" rgb1=".4 .6 .8" rgb2="0 0 0"
                 width="800" height="800" mark="random" markrgb="1 1 1"/>
    </asset>

    <asset>
        <texture name="grid" type="2d" builtin="checker" rgb1=".1 .2 .3" rgb2=".2 .3 .4" width="300" height="300"/>
        <material name="grid" texture="grid" texrepeat="1 1" texuniform="true" reflectance=".2"/>
        <material name="self" rgba=".7 .5 .3 1"/>
        <material name="decoration" rgba=".3 .5 .7 1"/>
        <material name="red" rgba=".7 .1 .1 1"/>
        <material name="green" rgba=".3 .8 .3 1"/>
    </asset>

    <worldbody>
        <light name="light" pos="0 0 6"/>
        <camera name="fixed" pos="0 -4 1" zaxis="0 -1 0"/>
        <geom name="floor" pos="0 0 -.05" size="4 4 .2" type="plane" material="grid"/>

        <geom name="rail1" type="capsule" pos="0  .07 1" zaxis="1 0 0" size="0.02 4" material="decoration"/>
        <geom name="rail2" type="capsule" pos="0 -.07 1" zaxis="1 0 0" size="0.02 4" material="decoration"/>

        <body name="cart" pos="0 0 1">
            <joint name="slider" type="slide" limited="false" axis="1 0 0" range="-1.8 1.8"/>
            <geom name="cart_geom" type="box" size="0.2 0.15 0.1" material="red" mass="1"
                  condim="3" contype="1" conaffinity="1"
                  margin="0.01" gap="0.0"
                  solref="0.02 1" solimp="0.95 0.95 0.001"/>
        </body>

        <body name="second_cart" pos="1 0 1">
            <joint name="second_slider_joint" type="slide" limited="false" axis="1 0 0" range="-1.8 1.8"/>
            <geom name="second_cart_geom" type="box" size="0.2 0.15 0.1" material="green" mass="1"
                  condim="3" contype="1" conaffinity="1"
                  margin="0.01" gap="0.0"
                  solref="0.02 1" solimp="0.95 0.95 0.001"/>
        </body>

    </worldbody>

    <actuator>
        <motor name="slide" joint="slider" gear="10" ctrllimited="false" ctrlrange="-1 1"/>
        <motor name="second_slider" joint="second_slider_joint" gear="10" ctrllimited="false" ctrlrange="-1 1"/>
    </actuator>

</mujoco>